Traceback (most recent call last):
  File "/Users/oskarhallatschek/anaconda3/lib/python3.10/site-packages/jupyter_cache/executors/utils.py", line 58, in single_nb_execution
    executenb(
  File "/Users/oskarhallatschek/anaconda3/lib/python3.10/site-packages/nbclient/client.py", line 1204, in execute
    return NotebookClient(nb=nb, resources=resources, km=km, **kwargs).execute()
  File "/Users/oskarhallatschek/anaconda3/lib/python3.10/site-packages/nbclient/util.py", line 84, in wrapped
    return just_run(coro(*args, **kwargs))
  File "/Users/oskarhallatschek/anaconda3/lib/python3.10/site-packages/nbclient/util.py", line 62, in just_run
    return loop.run_until_complete(coro)
  File "/Users/oskarhallatschek/anaconda3/lib/python3.10/asyncio/base_events.py", line 649, in run_until_complete
    return future.result()
  File "/Users/oskarhallatschek/anaconda3/lib/python3.10/site-packages/nbclient/client.py", line 663, in async_execute
    await self.async_execute_cell(
  File "/Users/oskarhallatschek/anaconda3/lib/python3.10/site-packages/nbclient/client.py", line 965, in async_execute_cell
    await self._check_raise_for_error(cell, cell_index, exec_reply)
  File "/Users/oskarhallatschek/anaconda3/lib/python3.10/site-packages/nbclient/client.py", line 862, in _check_raise_for_error
    raise CellExecutionError.from_cell_and_msg(cell, exec_reply_content)
nbclient.exceptions.CellExecutionError: An error occurred while executing the following cell:
------------------
# Plot kinetic energy time series inline
plt.figure(figsize=(8, 5))
for i in labeled_hot:
    plt.plot(time_series[i], color='red', label=f'Hot Particle {i}')
for i in labeled_cold:
    plt.plot(time_series[i], color='blue', label=f'Cold Particle {i}')
plt.xlabel('Time Step')
plt.ylabel('Kinetic Energy')
plt.title('Kinetic Energy Evolution of Labeled Particles')
plt.legend()
plt.show()

# Plot the kinetic energy histograms inline
plt.figure(figsize=(8, 5))
plt.hist(velini[:half_N].flatten()**2, bins=20, alpha=0.5, color='red', label='Initial KE (Hot)')
plt.hist(velini[half_N:].flatten()**2, bins=20, alpha=0.5, color='blue', label='Initial KE (Cold)')
plt.xlabel('Kinetic Energy')
plt.ylabel('Frequency')
plt.title('Initial Kinetic Energy Distribution')
plt.legend()
plt.show()

plt.figure(figsize=(8, 5))
plt.hist(vel[:half_N].flatten()**2, bins=20, alpha=0.5, color='red', label='Final KE (Hot)')
plt.hist(vel[half_N:].flatten()**2, bins=20, alpha=0.5, color='blue', label='Final KE (Cold)')
plt.xlabel('Kinetic Energy')
plt.ylabel('Frequency')
plt.title('Final Kinetic Energy Distribution')
plt.legend()
plt.show()
------------------

[0;31m---------------------------------------------------------------------------[0m
[0;31mNameError[0m                                 Traceback (most recent call last)
Cell [0;32mIn[2], line 15[0m
[1;32m     13[0m [38;5;66;03m# Plot the kinetic energy histograms inline[39;00m
[1;32m     14[0m plt[38;5;241m.[39mfigure(figsize[38;5;241m=[39m([38;5;241m8[39m, [38;5;241m5[39m))
[0;32m---> 15[0m plt[38;5;241m.[39mhist([43mvelini[49m[:half_N][38;5;241m.[39mflatten()[38;5;241m*[39m[38;5;241m*[39m[38;5;241m2[39m, bins[38;5;241m=[39m[38;5;241m20[39m, alpha[38;5;241m=[39m[38;5;241m0.5[39m, color[38;5;241m=[39m[38;5;124m'[39m[38;5;124mred[39m[38;5;124m'[39m, label[38;5;241m=[39m[38;5;124m'[39m[38;5;124mInitial KE (Hot)[39m[38;5;124m'[39m)
[1;32m     16[0m plt[38;5;241m.[39mhist(velini[half_N:][38;5;241m.[39mflatten()[38;5;241m*[39m[38;5;241m*[39m[38;5;241m2[39m, bins[38;5;241m=[39m[38;5;241m20[39m, alpha[38;5;241m=[39m[38;5;241m0.5[39m, color[38;5;241m=[39m[38;5;124m'[39m[38;5;124mblue[39m[38;5;124m'[39m, label[38;5;241m=[39m[38;5;124m'[39m[38;5;124mInitial KE (Cold)[39m[38;5;124m'[39m)
[1;32m     17[0m plt[38;5;241m.[39mxlabel([38;5;124m'[39m[38;5;124mKinetic Energy[39m[38;5;124m'[39m)

[0;31mNameError[0m: name 'velini' is not defined
NameError: name 'velini' is not defined

