Traceback (most recent call last):
  File "/Users/oskarhallatschek/anaconda3/lib/python3.10/site-packages/jupyter_cache/executors/utils.py", line 58, in single_nb_execution
    executenb(
  File "/Users/oskarhallatschek/anaconda3/lib/python3.10/site-packages/nbclient/client.py", line 1204, in execute
    return NotebookClient(nb=nb, resources=resources, km=km, **kwargs).execute()
  File "/Users/oskarhallatschek/anaconda3/lib/python3.10/site-packages/nbclient/util.py", line 84, in wrapped
    return just_run(coro(*args, **kwargs))
  File "/Users/oskarhallatschek/anaconda3/lib/python3.10/site-packages/nbclient/util.py", line 62, in just_run
    return loop.run_until_complete(coro)
  File "/Users/oskarhallatschek/anaconda3/lib/python3.10/asyncio/base_events.py", line 649, in run_until_complete
    return future.result()
  File "/Users/oskarhallatschek/anaconda3/lib/python3.10/site-packages/nbclient/client.py", line 663, in async_execute
    await self.async_execute_cell(
  File "/Users/oskarhallatschek/anaconda3/lib/python3.10/site-packages/nbclient/client.py", line 965, in async_execute_cell
    await self._check_raise_for_error(cell, cell_index, exec_reply)
  File "/Users/oskarhallatschek/anaconda3/lib/python3.10/site-packages/nbclient/client.py", line 862, in _check_raise_for_error
    raise CellExecutionError.from_cell_and_msg(cell, exec_reply_content)
nbclient.exceptions.CellExecutionError: An error occurred while executing the following cell:
------------------
import matplotlib.pyplot as plt
import networkx as nx

# Parameters
num_spins = 10  # Number of Ising spins

# Create an all-to-all graph
G = nx.complete_graph(num_spins)

# Plotting
plt.figure(figsize=(3, 3))
pos = nx.circular_layout(G)  # Position nodes in a circle
nx.draw(G, pos, with_labels=True, node_color='lightblue', node_size=500, edge_color='gray')
plt.title('All-to-All Graph of 10 Ising Spins')
plt.savefig("all-to-all.png")
plt.show()

------------------

[0;31m---------------------------------------------------------------------------[0m
[0;31mTypeError[0m                                 Traceback (most recent call last)
Cell [0;32mIn[2], line 13[0m
[1;32m     11[0m plt[38;5;241m.[39mfigure(figsize[38;5;241m=[39m([38;5;241m3[39m, [38;5;241m3[39m))
[1;32m     12[0m pos [38;5;241m=[39m nx[38;5;241m.[39mcircular_layout(G)  [38;5;66;03m# Position nodes in a circle[39;00m
[0;32m---> 13[0m [43mnx[49m[38;5;241;43m.[39;49m[43mdraw[49m[43m([49m[43mG[49m[43m,[49m[43m [49m[43mpos[49m[43m,[49m[43m [49m[43mwith_labels[49m[38;5;241;43m=[39;49m[38;5;28;43;01mTrue[39;49;00m[43m,[49m[43m [49m[43mnode_color[49m[38;5;241;43m=[39;49m[38;5;124;43m'[39;49m[38;5;124;43mlightblue[39;49m[38;5;124;43m'[39;49m[43m,[49m[43m [49m[43mnode_size[49m[38;5;241;43m=[39;49m[38;5;241;43m500[39;49m[43m,[49m[43m [49m[43medge_color[49m[38;5;241;43m=[39;49m[38;5;124;43m'[39;49m[38;5;124;43mgray[39;49m[38;5;124;43m'[39;49m[43m)[49m
[1;32m     14[0m plt[38;5;241m.[39mtitle([38;5;124m'[39m[38;5;124mAll-to-All Graph of 10 Ising Spins[39m[38;5;124m'[39m)
[1;32m     15[0m plt[38;5;241m.[39msavefig([38;5;124m"[39m[38;5;124mall-to-all.png[39m[38;5;124m"[39m)

File [0;32m~/anaconda3/lib/python3.10/site-packages/networkx/drawing/nx_pylab.py:113[0m, in [0;36mdraw[0;34m(G, pos, ax, **kwds)[0m
[1;32m    111[0m cf[38;5;241m.[39mset_facecolor([38;5;124m"[39m[38;5;124mw[39m[38;5;124m"[39m)
[1;32m    112[0m [38;5;28;01mif[39;00m ax [38;5;129;01mis[39;00m [38;5;28;01mNone[39;00m:
[0;32m--> 113[0m     [38;5;28;01mif[39;00m [43mcf[49m[38;5;241;43m.[39;49m[43m_axstack[49m[43m([49m[43m)[49m [38;5;129;01mis[39;00m [38;5;28;01mNone[39;00m:
[1;32m    114[0m         ax [38;5;241m=[39m cf[38;5;241m.[39madd_axes(([38;5;241m0[39m, [38;5;241m0[39m, [38;5;241m1[39m, [38;5;241m1[39m))
[1;32m    115[0m     [38;5;28;01melse[39;00m:

[0;31mTypeError[0m: '_AxesStack' object is not callable
TypeError: '_AxesStack' object is not callable

